Workbook
Name ActividadPasante: Referencias!$Q$6:$Q$8
Name ElementoBase: Referencias!$D$6:$D$13
Name FormasGeom: Referencias!$L$6:$L$12
Name MaterialBase: Referencias!$H$6:$H$9
Name PasantesComunes: Referencias!$U$6:$U$20
Name ProductosHilti: Referencias!$Y$6:$Y$21

Sheet Informe - Planilla
A2: Para / To: | C2: De / From: | E2: Fecha /Date: | F2: OBSERVACIONES:
A3: CLIENTE | C3: DEPARTAMENTO | E3: =TODAY() -> 42432
A4: Nombre de destinatario | C4: Nombre de remitente
A5: Asunto / Subject: | E5: Memo:
A6: Descripción del proyecto; incluir nombre de la obra/proyecto. | E6: HES-FS-…
F8: ELEMENTO BASE | I8: PERFORACION | M8: ELEMENTO PASANTE | T8: SELLO CORTAFUEGO HILTI | W8: RESULTADOS
A9: CODIGO | B9: UBICACIÓN | C9: CERTIF. | D9: COMENTARIOS | E9: REGISTRO GRÁFICO | F9: MATERIAL | G9: TIPO | H9: ESPESOR tw | I9: FORMA | J9: X | K9: Y | L9: η | M9: TIPO | N9: # | O9: USO | P9: a | Q9: b | R9: LLENADO % | S9: AS min/max | T9: PRODUCTO HILTI | U9: # | V9: ESPESOR ds | W9: Ag | X9: Ap | Y9: As (Ag – Ap) | Z9: SUBTOTAL (As ∙ ds) | AA9: desp % | AB9: CANTIDAD NETA
A10: 1A | C10: W-L-5257 | D10: Tub metalica <4 con aislamiento | F10: Drywall/Yeso | I10: Circular | J10: 12 | M10: Tubería metal | N10: 1 | O10: IA | P10: 10 | T10: CP 606 | U10: 2 | V10: 1.6 | W10: =IF($A10="", "", IF(T10="","", IF(I10="Circular",PI()*(J10^2)/4, IF(I10="Rectangular", J10*K10, IF(I10="Irregular", J10*K10, IF(I10="Junta delgada", J10*K10, IF(I10="Junta steeldeck",(K10+(IF(L10=0,1,IF(L10=1,2.5,IF(L10=2,Referencias!$BA$19,IF(L10=3,Referencias!$BA$34,IF(L10=4,4.5,L10)))))/100 ))*J10, IF(I10="Junta irregular", L10, IF(I10="Junta perimetral", J10*(K10), 0 ))))))))) -> 113.09734 | X10: =IF($A10="", "", IF(M10="","", IF(IFERROR(SEARCH("bandeja",M10),0)>0, N10*P10*Q10*R10, IF(IFERROR(SEARCH("tubería",M10),0)>0, N10*PI()*(P10^2)/4, IF(IFERROR(SEARCH("circular",M10),0)>0, N10*PI()*(P10^2)/4, IF(IFERROR(SEARCH("rectangular",M10),0)>0, N10*P10*Q10, IF(IFERROR(SEARCH("cable",M10),0)>0, N10*PI()*(P10^2)/4, IF(IFERROR(SEARCH("caja",M10),0)>0, N10*P10*Q10, IF( IFERROR(SEARCH("blindobarra",M10),0)>0, N10*P10*Q10, IF( IFERROR(SEARCH("ninguno",M10),0)>0, 0, P10 )))))))))) -> 78.539816 | Y10: =IF(T10="","",$W10-SUMIFS($X:$X,$A:$A,$A10)) -> 34.557519 | Z10: =IF(T10="","", IF(OR($T10=Referencias!$Y$20,$T10=Referencias!$Y$21),1, IF(OR($T10=Referencias!$Y$18,$T10=Referencias!$Y$19),( PI()*((V10*P10)+(2*0.48*( V10*((0+(V10-1))/2) ))) )/100, V10*Y10 ))) -> 55.292031 | AA10: 0.05 | AB10: =IF(T10="","",Z10*U10*(1+AA10)) -> 116.11326
A11: 1A | C11: W-L-1297 | D11: Tub metalica <4 sin aislamiento | I11: Circular | J11: 12 | T11: CP 606 | U11: 2 | V11: 3.2 | W11: =IF($A11="", "", IF(T11="","", IF(I11="Circular",PI()*(J11^2)/4, IF(I11="Rectangular", J11*K11, IF(I11="Irregular", J11*K11, IF(I11="Junta delgada", J11*K11, IF(I11="Junta steeldeck",(K11+(IF(L11=0,1,IF(L11=1,2.5,IF(L11=2,Referencias!$BA$19,IF(L11=3,Referencias!$BA$34,IF(L11=4,4.5,L11)))))/100 ))*J11, IF(I11="Junta irregular", L11, IF(I11="Junta perimetral", J11*(K11), 0 ))))))))) -> 113.09734 | X11: =IF($A11="", "", IF(M11="","", IF(IFERROR(SEARCH("bandeja",M11),0)>0, N11*P11*Q11*R11, IF(IFERROR(SEARCH("tubería",M11),0)>0, N11*PI()*(P11^2)/4, IF(IFERROR(SEARCH("circular",M11),0)>0, N11*PI()*(P11^2)/4, IF(IFERROR(SEARCH("rectangular",M11),0)>0, N11*P11*Q11, IF(IFERROR(SEARCH("cable",M11),0)>0, N11*PI()*(P11^2)/4, IF(IFERROR(SEARCH("caja",M11),0)>0, N11*P11*Q11, IF( IFERROR(SEARCH("blindobarra",M11),0)>0, N11*P11*Q11, IF( IFERROR(SEARCH("ninguno",M11),0)>0, 0, P11 )))))))))) | Y11: =IF(T11="","",$W11-SUMIFS($X:$X,$A:$A,$A11)) -> 34.557519 | Z11: =IF(T11="","", IF(OR($T11=Referencias!$Y$20,$T11=Referencias!$Y$21),1, IF(OR($T11=Referencias!$Y$18,$T11=Referencias!$Y$19),( PI()*((V11*P11)+(2*0.48*( V11*((0+(V11-1))/2) ))) )/100, V11*Y11 ))) -> 110.58406 | AA11: 0.05 | AB11: =IF(T11="","",Z11*U11*(1+AA11)) -> 232.22653
A12: 1B | C12: W-L-5225 | D12: Tub no metalica <4 con aislamiento | F12: Drywall/Yeso | I12: Circular | J12: 12 | M12: Tubería no metal | N12: 1 | O12: IA | P12: 10 | T12: CP 648E 1" | U12: 2 | V12: 3 | W12: =IF($A12="", "", IF(T12="","", IF(I12="Circular",PI()*(J12^2)/4, IF(I12="Rectangular", J12*K12, IF(I12="Irregular", J12*K12, IF(I12="Junta delgada", J12*K12, IF(I12="Junta steeldeck",(K12+(IF(L12=0,1,IF(L12=1,2.5,IF(L12=2,Referencias!$BA$19,IF(L12=3,Referencias!$BA$34,IF(L12=4,4.5,L12)))))/100 ))*J12, IF(I12="Junta irregular", L12, IF(I12="Junta perimetral", J12*(K12), 0 ))))))))) -> 113.09734 | X12: =IF($A12="", "", IF(M12="","", IF(IFERROR(SEARCH("bandeja",M12),0)>0, N12*P12*Q12*R12, IF(IFERROR(SEARCH("tubería",M12),0)>0, N12*PI()*(P12^2)/4, IF(IFERROR(SEARCH("circular",M12),0)>0, N12*PI()*(P12^2)/4, IF(IFERROR(SEARCH("rectangular",M12),0)>0, N12*P12*Q12, IF(IFERROR(SEARCH("cable",M12),0)>0, N12*PI()*(P12^2)/4, IF(IFERROR(SEARCH("caja",M12),0)>0, N12*P12*Q12, IF( IFERROR(SEARCH("blindobarra",M12),0)>0, N12*P12*Q12, IF( IFERROR(SEARCH("ninguno",M12),0)>0, 0, P12 )))))))))) -> 78.539816 | Y12: =IF(T12="","",$W12-SUMIFS($X:$X,$A:$A,$A12)) -> 34.557519 | Z12: =IF(T12="","", IF(OR($T12=Referencias!$Y$20,$T12=Referencias!$Y$21),1, IF(OR($T12=Referencias!$Y$18,$T12=Referencias!$Y$19),( PI()*((V12*P12)+(2*0.48*( V12*((0+(V12-1))/2) ))) )/100, V12*Y12 ))) -> 1.0329557 | AA12: 0.05 | AB12: =IF(T12="","",Z12*U12*(1+AA12)) -> 2.1692069
A13: 1B | I13: Circular | J13: 12 | T13: FS-ONE Max | U13: 1 | V13: 0.1 | W13: =IF($A13="", "", IF(T13="","", IF(I13="Circular",PI()*(J13^2)/4, IF(I13="Rectangular", J13*K13, IF(I13="Irregular", J13*K13, IF(I13="Junta delgada", J13*K13, IF(I13="Junta steeldeck",(K13+(IF(L13=0,1,IF(L13=1,2.5,IF(L13=2,Referencias!$BA$19,IF(L13=3,Referencias!$BA$34,IF(L13=4,4.5,L13)))))/100 ))*J13, IF(I13="Junta irregular", L13, IF(I13="Junta perimetral", J13*(K13), 0 ))))))))) -> 113.09734 | X13: =IF($A13="", "", IF(M13="","", IF(IFERROR(SEARCH("bandeja",M13),0)>0, N13*P13*Q13*R13, IF(IFERROR(SEARCH("tubería",M13),0)>0, N13*PI()*(P13^2)/4, IF(IFERROR(SEARCH("circular",M13),0)>0, N13*PI()*(P13^2)/4, IF(IFERROR(SEARCH("rectangular",M13),0)>0, N13*P13*Q13, IF(IFERROR(SEARCH("cable",M13),0)>0, N13*PI()*(P13^2)/4, IF(IFERROR(SEARCH("caja",M13),0)>0, N13*P13*Q13, IF( IFERROR(SEARCH("blindobarra",M13),0)>0, N13*P13*Q13, IF( IFERROR(SEARCH("ninguno",M13),0)>0, 0, P13 )))))))))) | Y13: =IF(T13="","",$W13-SUMIFS($X:$X,$A:$A,$A13)) -> 34.557519 | Z13: =IF(T13="","", IF(OR($T13=Referencias!$Y$20,$T13=Referencias!$Y$21),1, IF(OR($T13=Referencias!$Y$18,$T13=Referencias!$Y$19),( PI()*((V13*P13)+(2*0.48*( V13*((0+(V13-1))/2) ))) )/100, V13*Y13 ))) -> 3.4557519 | AA13: 0.05 | AB13: =IF(T13="","",Z13*U13*(1+AA13)) -> 3.6285395
A14: 2A | C14: W-L-4060 | D14: Bandejas + cableado | F14: Drywall/Yeso | I14: Rectangular | J14: 32 | K14: 12 | M14: Bandeja PC | N14: 1 | O14: IA | P14: 30 | Q14: 10 | R14: 0.65 | T14: FS-ONE Max | U14: 2 | V14: 1.5 | W14: =IF($A14="", "", IF(T14="","", IF(I14="Circular",PI()*(J14^2)/4, IF(I14="Rectangular", J14*K14, IF(I14="Irregular", J14*K14, IF(I14="Junta delgada", J14*K14, IF(I14="Junta steeldeck",(K14+(IF(L14=0,1,IF(L14=1,2.5,IF(L14=2,Referencias!$BA$19,IF(L14=3,Referencias!$BA$34,IF(L14=4,4.5,L14)))))/100 ))*J14, IF(I14="Junta irregular", L14, IF(I14="Junta perimetral", J14*(K14), 0 ))))))))) -> 384 | X14: =IF($A14="", "", IF(M14="","", IF(IFERROR(SEARCH("bandeja",M14),0)>0, N14*P14*Q14*R14, IF(IFERROR(SEARCH("tubería",M14),0)>0, N14*PI()*(P14^2)/4, IF(IFERROR(SEARCH("circular",M14),0)>0, N14*PI()*(P14^2)/4, IF(IFERROR(SEARCH("rectangular",M14),0)>0, N14*P14*Q14, IF(IFERROR(SEARCH("cable",M14),0)>0, N14*PI()*(P14^2)/4, IF(IFERROR(SEARCH("caja",M14),0)>0, N14*P14*Q14, IF( IFERROR(SEARCH("blindobarra",M14),0)>0, N14*P14*Q14, IF( IFERROR(SEARCH("ninguno",M14),0)>0, 0, P14 )))))))))) -> 195 | Y14: =IF(T14="","",$W14-SUMIFS($X:$X,$A:$A,$A14)) -> 189 | Z14: =IF(T14="","", IF(OR($T14=Referencias!$Y$20,$T14=Referencias!$Y$21),1, IF(OR($T14=Referencias!$Y$18,$T14=Referencias!$Y$19),( PI()*((V14*P14)+(2*0.48*( V14*((0+(V14-1))/2) ))) )/100, V14*Y14 ))) -> 283.5 | AA14: 0.05 | AB14: =IF(T14="","",Z14*U14*(1+AA14)) -> 595.35
A15: 2A | I15: Rectangular | J15: 32 | K15: 12 | T15: CFS-WB | U15: 1 | V15: 13 | W15: =IF($A15="", "", IF(T15="","", IF(I15="Circular",PI()*(J15^2)/4, IF(I15="Rectangular", J15*K15, IF(I15="Irregular", J15*K15, IF(I15="Junta delgada", J15*K15, IF(I15="Junta steeldeck",(K15+(IF(L15=0,1,IF(L15=1,2.5,IF(L15=2,Referencias!$BA$19,IF(L15=3,Referencias!$BA$34,IF(L15=4,4.5,L15)))))/100 ))*J15, IF(I15="Junta irregular", L15, IF(I15="Junta perimetral", J15*(K15), 0 ))))))))) -> 384 | X15: =IF($A15="", "", IF(M15="","", IF(IFERROR(SEARCH("bandeja",M15),0)>0, N15*P15*Q15*R15, IF(IFERROR(SEARCH("tubería",M15),0)>0, N15*PI()*(P15^2)/4, IF(IFERROR(SEARCH("circular",M15),0)>0, N15*PI()*(P15^2)/4, IF(IFERROR(SEARCH("rectangular",M15),0)>0, N15*P15*Q15, IF(IFERROR(SEARCH("cable",M15),0)>0, N15*PI()*(P15^2)/4, IF(IFERROR(SEARCH("caja",M15),0)>0, N15*P15*Q15, IF( IFERROR(SEARCH("blindobarra",M15),0)>0, N15*P15*Q15, IF( IFERROR(SEARCH("ninguno",M15),0)>0, 0, P15 )))))))))) | Y15: =IF(T15="","",$W15-SUMIFS($X:$X,$A:$A,$A15)) -> 189 | Z15: =IF(T15="","", IF(OR($T15=Referencias!$Y$20,$T15=Referencias!$Y$21),1, IF(OR($T15=Referencias!$Y$18,$T15=Referencias!$Y$19),( PI()*((V15*P15)+(2*0.48*( V15*((0+(V15-1))/2) ))) )/100, V15*Y15 ))) -> 2457 | AA15: 0.05 | AB15: =IF(T15="","",Z15*U15*(1+AA15)) -> 2579.85
A16: 2B | C16: BW-S-0001 | D16: Juntas <2cm | F16: Drywall/Yeso | I16: Junta delgada | J16: 100 | K16: 1 | T16: CP 606 | U16: 2 | V16: 3.2 | W16: =IF($A16="", "", IF(T16="","", IF(I16="Circular",PI()*(J16^2)/4, IF(I16="Rectangular", J16*K16, IF(I16="Irregular", J16*K16, IF(I16="Junta delgada", J16*K16, IF(I16="Junta steeldeck",(K16+(IF(L16=0,1,IF(L16=1,2.5,IF(L16=2,Referencias!$BA$19,IF(L16=3,Referencias!$BA$34,IF(L16=4,4.5,L16)))))/100 ))*J16, IF(I16="Junta irregular", L16, IF(I16="Junta perimetral", J16*(K16), 0 ))))))))) -> 100 | X16: =IF($A16="", "", IF(M16="","", IF(IFERROR(SEARCH("bandeja",M16),0)>0, N16*P16*Q16*R16, IF(IFERROR(SEARCH("tubería",M16),0)>0, N16*PI()*(P16^2)/4, IF(IFERROR(SEARCH("circular",M16),0)>0, N16*PI()*(P16^2)/4, IF(IFERROR(SEARCH("rectangular",M16),0)>0, N16*P16*Q16, IF(IFERROR(SEARCH("cable",M16),0)>0, N16*PI()*(P16^2)/4, IF(IFERROR(SEARCH("caja",M16),0)>0, N16*P16*Q16, IF( IFERROR(SEARCH("blindobarra",M16),0)>0, N16*P16*Q16, IF( IFERROR(SEARCH("ninguno",M16),0)>0, 0, P16 )))))))))) | Y16: =IF(T16="","",$W16-SUMIFS($X:$X,$A:$A,$A16)) -> 100 | Z16: =IF(T16="","", IF(OR($T16=Referencias!$Y$20,$T16=Referencias!$Y$21),1, IF(OR($T16=Referencias!$Y$18,$T16=Referencias!$Y$19),( PI()*((V16*P16)+(2*0.48*( V16*((0+(V16-1))/2) ))) )/100, V16*Y16 ))) -> 320 | AA16: 0.05 | AB16: =IF(T16="","",Z16*U16*(1+AA16)) -> 672
A17: 2B | C17: HW-D-0083 | W17: =IF($A17="", "", IF(T17="","", IF(I17="Circular",PI()*(J17^2)/4, IF(I17="Rectangular", J17*K17, IF(I17="Irregular", J17*K17, IF(I17="Junta delgada", J17*K17, IF(I17="Junta steeldeck",(K17+(IF(L17=0,1,IF(L17=1,2.5,IF(L17=2,Referencias!$BA$19,IF(L17=3,Referencias!$BA$34,IF(L17=4,4.5,L17)))))/100 ))*J17, IF(I17="Junta irregular", L17, IF(I17="Junta perimetral", J17*(K17), 0 ))))))))) | X17: =IF($A17="", "", IF(M17="","", IF(IFERROR(SEARCH("bandeja",M17),0)>0, N17*P17*Q17*R17, IF(IFERROR(SEARCH("tubería",M17),0)>0, N17*PI()*(P17^2)/4, IF(IFERROR(SEARCH("circular",M17),0)>0, N17*PI()*(P17^2)/4, IF(IFERROR(SEARCH("rectangular",M17),0)>0, N17*P17*Q17, IF(IFERROR(SEARCH("cable",M17),0)>0, N17*PI()*(P17^2)/4, IF(IFERROR(SEARCH("caja",M17),0)>0, N17*P17*Q17, IF( IFERROR(SEARCH("blindobarra",M17),0)>0, N17*P17*Q17, IF( IFERROR(SEARCH("ninguno",M17),0)>0, 0, P17 )))))))))) | Y17: =IF(T17="","",$W17-SUMIFS($X:$X,$A:$A,$A17)) | Z17: =IF(T17="","", IF(OR($T17=Referencias!$Y$20,$T17=Referencias!$Y$21),1, IF(OR($T17=Referencias!$Y$18,$T17=Referencias!$Y$19),( PI()*((V17*P17)+(2*0.48*( V17*((0+(V17-1))/2) ))) )/100, V17*Y17 ))) | AA17: 0.05 | AB17: =IF(T17="","",Z17*U17*(1+AA17))
A18: 3A | W18: =IF($A18="", "", IF(T18="","", IF(I18="Circular",PI()*(J18^2)/4, IF(I18="Rectangular", J18*K18, IF(I18="Irregular", J18*K18, IF(I18="Junta delgada", J18*K18, IF(I18="Junta steeldeck",(K18+(IF(L18=0,1,IF(L18=1,2.5,IF(L18=2,Referencias!$BA$19,IF(L18=3,Referencias!$BA$34,IF(L18=4,4.5,L18)))))/100 ))*J18, IF(I18="Junta irregular", L18, IF(I18="Junta perimetral", J18*(K18), 0 ))))))))) | X18: =IF($A18="", "", IF(M18="","", IF(IFERROR(SEARCH("bandeja",M18),0)>0, N18*P18*Q18*R18, IF(IFERROR(SEARCH("tubería",M18),0)>0, N18*PI()*(P18^2)/4, IF(IFERROR(SEARCH("circular",M18),0)>0, N18*PI()*(P18^2)/4, IF(IFERROR(SEARCH("rectangular",M18),0)>0, N18*P18*Q18, IF(IFERROR(SEARCH("cable",M18),0)>0, N18*PI()*(P18^2)/4, IF(IFERROR(SEARCH("caja",M18),0)>0, N18*P18*Q18, IF( IFERROR(SEARCH("blindobarra",M18),0)>0, N18*P18*Q18, IF( IFERROR(SEARCH("ninguno",M18),0)>0, 0, P18 )))))))))) | Y18: =IF(T18="","",$W18-SUMIFS($X:$X,$A:$A,$A18)) | Z18: =IF(T18="","", IF(OR($T18=Referencias!$Y$20,$T18=Referencias!$Y$21),1, IF(OR($T18=Referencias!$Y$18,$T18=Referencias!$Y$19),( PI()*((V18*P18)+(2*0.48*( V18*((0+(V18-1))/2) ))) )/100, V18*Y18 ))) | AB18: =IF(T18="","",Z18*U18*(1+AA18))
A19: 3A | W19: =IF($A19="", "", IF(T19="","", IF(I19="Circular",PI()*(J19^2)/4, IF(I19="Rectangular", J19*K19, IF(I19="Irregular", J19*K19, IF(I19="Junta delgada", J19*K19, IF(I19="Junta steeldeck",(K19+(IF(L19=0,1,IF(L19=1,2.5,IF(L19=2,Referencias!$BA$19,IF(L19=3,Referencias!$BA$34,IF(L19=4,4.5,L19)))))/100 ))*J19, IF(I19="Junta irregular", L19, IF(I19="Junta perimetral", J19*(K19), 0 ))))))))) | X19: =IF($A19="", "", IF(M19="","", IF(IFERROR(SEARCH("bandeja",M19),0)>0, N19*P19*Q19*R19, IF(IFERROR(SEARCH("tubería",M19),0)>0, N19*PI()*(P19^2)/4, IF(IFERROR(SEARCH("circular",M19),0)>0, N19*PI()*(P19^2)/4, IF(IFERROR(SEARCH("rectangular",M19),0)>0, N19*P19*Q19, IF(IFERROR(SEARCH("cable",M19),0)>0, N19*PI()*(P19^2)/4, IF(IFERROR(SEARCH("caja",M19),0)>0, N19*P19*Q19, IF( IFERROR(SEARCH("blindobarra",M19),0)>0, N19*P19*Q19, IF( IFERROR(SEARCH("ninguno",M19),0)>0, 0, P19 )))))))))) | Y19: =IF(T19="","",$W19-SUMIFS($X:$X,$A:$A,$A19)) | Z19: =IF(T19="","", IF(OR($T19=Referencias!$Y$20,$T19=Referencias!$Y$21),1, IF(OR($T19=Referencias!$Y$18,$T19=Referencias!$Y$19),( PI()*((V19*P19)+(2*0.48*( V19*((0+(V19-1))/2) ))) )/100, V19*Y19 ))) | AB19: =IF(T19="","",Z19*U19*(1+AA19))
A20: 3B | W20: =IF($A20="", "", IF(T20="","", IF(I20="Circular",PI()*(J20^2)/4, IF(I20="Rectangular", J20*K20, IF(I20="Irregular", J20*K20, IF(I20="Junta delgada", J20*K20, IF(I20="Junta steeldeck",(K20+(IF(L20=0,1,IF(L20=1,2.5,IF(L20=2,Referencias!$BA$19,IF(L20=3,Referencias!$BA$34,IF(L20=4,4.5,L20)))))/100 ))*J20, IF(I20="Junta irregular", L20, IF(I20="Junta perimetral", J20*(K20), 0 ))))))))) | X20: =IF($A20="", "", IF(M20="","", IF(IFERROR(SEARCH("bandeja",M20),0)>0, N20*P20*Q20*R20, IF(IFERROR(SEARCH("tubería",M20),0)>0, N20*PI()*(P20^2)/4, IF(IFERROR(SEARCH("circular",M20),0)>0, N20*PI()*(P20^2)/4, IF(IFERROR(SEARCH("rectangular",M20),0)>0, N20*P20*Q20, IF(IFERROR(SEARCH("cable",M20),0)>0, N20*PI()*(P20^2)/4, IF(IFERROR(SEARCH("caja",M20),0)>0, N20*P20*Q20, IF( IFERROR(SEARCH("blindobarra",M20),0)>0, N20*P20*Q20, IF( IFERROR(SEARCH("ninguno",M20),0)>0, 0, P20 )))))))))) | Y20: =IF(T20="","",$W20-SUMIFS($X:$X,$A:$A,$A20)) | Z20: =IF(T20="","", IF(OR($T20=Referencias!$Y$20,$T20=Referencias!$Y$21),1, IF(OR($T20=Referencias!$Y$18,$T20=Referencias!$Y$19),( PI()*((V20*P20)+(2*0.48*( V20*((0+(V20-1))/2) ))) )/100, V20*Y20 ))) | AB20: =IF(T20="","",Z20*U20*(1+AA20))
A21: 3B | W21: =IF($A21="", "", IF(T21="","", IF(I21="Circular",PI()*(J21^2)/4, IF(I21="Rectangular", J21*K21, IF(I21="Irregular", J21*K21, IF(I21="Junta delgada", J21*K21, IF(I21="Junta steeldeck",(K21+(IF(L21=0,1,IF(L21=1,2.5,IF(L21=2,Referencias!$BA$19,IF(L21=3,Referencias!$BA$34,IF(L21=4,4.5,L21)))))/100 ))*J21, IF(I21="Junta irregular", L21, IF(I21="Junta perimetral", J21*(K21), 0 ))))))))) | X21: =IF($A21="", "", IF(M21="","", IF(IFERROR(SEARCH("bandeja",M21),0)>0, N21*P21*Q21*R21, IF(IFERROR(SEARCH("tubería",M21),0)>0, N21*PI()*(P21^2)/4, IF(IFERROR(SEARCH("circular",M21),0)>0, N21*PI()*(P21^2)/4, IF(IFERROR(SEARCH("rectangular",M21),0)>0, N21*P21*Q21, IF(IFERROR(SEARCH("cable",M21),0)>0, N21*PI()*(P21^2)/4, IF(IFERROR(SEARCH("caja",M21),0)>0, N21*P21*Q21, IF( IFERROR(SEARCH("blindobarra",M21),0)>0, N21*P21*Q21, IF( IFERROR(SEARCH("ninguno",M21),0)>0, 0, P21 )))))))))) | Y21: =IF(T21="","",$W21-SUMIFS($X:$X,$A:$A,$A21)) | Z21: =IF(T21="","", IF(OR($T21=Referencias!$Y$20,$T21=Referencias!$Y$21),1, IF(OR($T21=Referencias!$Y$18,$T21=Referencias!$Y$19),( PI()*((V21*P21)+(2*0.48*( V21*((0+(V21-1))/2) ))) )/100, V21*Y21 ))) | AB21: =IF(T21="","",Z21*U21*(1+AA21))
A22: 4A | W22: =IF($A22="", "", IF(T22="","", IF(I22="Circular",PI()*(J22^2)/4, IF(I22="Rectangular", J22*K22, IF(I22="Irregular", J22*K22, IF(I22="Junta delgada", J22*K22, IF(I22="Junta steeldeck",(K22+(IF(L22=0,1,IF(L22=1,2.5,IF(L22=2,Referencias!$BA$19,IF(L22=3,Referencias!$BA$34,IF(L22=4,4.5,L22)))))/100 ))*J22, IF(I22="Junta irregular", L22, IF(I22="Junta perimetral", J22*(K22), 0 ))))))))) | X22: =IF($A22="", "", IF(M22="","", IF(IFERROR(SEARCH("bandeja",M22),0)>0, N22*P22*Q22*R22, IF(IFERROR(SEARCH("tubería",M22),0)>0, N22*PI()*(P22^2)/4, IF(IFERROR(SEARCH("circular",M22),0)>0, N22*PI()*(P22^2)/4, IF(IFERROR(SEARCH("rectangular",M22),0)>0, N22*P22*Q22, IF(IFERROR(SEARCH("cable",M22),0)>0, N22*PI()*(P22^2)/4, IF(IFERROR(SEARCH("caja",M22),0)>0, N22*P22*Q22, IF( IFERROR(SEARCH("blindobarra",M22),0)>0, N22*P22*Q22, IF( IFERROR(SEARCH("ninguno",M22),0)>0, 0, P22 )))))))))) | Y22: =IF(T22="","",$W22-SUMIFS($X:$X,$A:$A,$A22)) | Z22: =IF(T22="","", IF(OR($T22=Referencias!$Y$20,$T22=Referencias!$Y$21),1, IF(OR($T22=Referencias!$Y$18,$T22=Referencias!$Y$19),( PI()*((V22*P22)+(2*0.48*( V22*((0+(V22-1))/2) ))) )/100, V22*Y22 ))) | AB22: =IF(T22="","",Z22*U22*(1+AA22))
A23: 4A | W23: =IF($A23="", "", IF(T23="","", IF(I23="Circular",PI()*(J23^2)/4, IF(I23="Rectangular", J23*K23, IF(I23="Irregular", J23*K23, IF(I23="Junta delgada", J23*K23, IF(I23="Junta steeldeck",(K23+(IF(L23=0,1,IF(L23=1,2.5,IF(L23=2,Referencias!$BA$19,IF(L23=3,Referencias!$BA$34,IF(L23=4,4.5,L23)))))/100 ))*J23, IF(I23="Junta irregular", L23, IF(I23="Junta perimetral", J23*(K23), 0 ))))))))) | X23: =IF($A23="", "", IF(M23="","", IF(IFERROR(SEARCH("bandeja",M23),0)>0, N23*P23*Q23*R23, IF(IFERROR(SEARCH("tubería",M23),0)>0, N23*PI()*(P23^2)/4, IF(IFERROR(SEARCH("circular",M23),0)>0, N23*PI()*(P23^2)/4, IF(IFERROR(SEARCH("rectangular",M23),0)>0, N23*P23*Q23, IF(IFERROR(SEARCH("cable",M23),0)>0, N23*PI()*(P23^2)/4, IF(IFERROR(SEARCH("caja",M23),0)>0, N23*P23*Q23, IF( IFERROR(SEARCH("blindobarra",M23),0)>0, N23*P23*Q23, IF( IFERROR(SEARCH("ninguno",M23),0)>0, 0, P23 )))))))))) | Y23: =IF(T23="","",$W23-SUMIFS($X:$X,$A:$A,$A23)) | Z23: =IF(T23="","", IF(OR($T23=Referencias!$Y$20,$T23=Referencias!$Y$21),1, IF(OR($T23=Referencias!$Y$18,$T23=Referencias!$Y$19),( PI()*((V23*P23)+(2*0.48*( V23*((0+(V23-1))/2) ))) )/100, V23*Y23 ))) | AB23: =IF(T23="","",Z23*U23*(1+AA23))
A24: 4B | W24: =IF($A24="", "", IF(T24="","", IF(I24="Circular",PI()*(J24^2)/4, IF(I24="Rectangular", J24*K24, IF(I24="Irregular", J24*K24, IF(I24="Junta delgada", J24*K24, IF(I24="Junta steeldeck",(K24+(IF(L24=0,1,IF(L24=1,2.5,IF(L24=2,Referencias!$BA$19,IF(L24=3,Referencias!$BA$34,IF(L24=4,4.5,L24)))))/100 ))*J24, IF(I24="Junta irregular", L24, IF(I24="Junta perimetral", J24*(K24), 0 ))))))))) | X24: =IF($A24="", "", IF(M24="","", IF(IFERROR(SEARCH("bandeja",M24),0)>0, N24*P24*Q24*R24, IF(IFERROR(SEARCH("tubería",M24),0)>0, N24*PI()*(P24^2)/4, IF(IFERROR(SEARCH("circular",M24),0)>0, N24*PI()*(P24^2)/4, IF(IFERROR(SEARCH("rectangular",M24),0)>0, N24*P24*Q24, IF(IFERROR(SEARCH("cable",M24),0)>0, N24*PI()*(P24^2)/4, IF(IFERROR(SEARCH("caja",M24),0)>0, N24*P24*Q24, IF( IFERROR(SEARCH("blindobarra",M24),0)>0, N24*P24*Q24, IF( IFERROR(SEARCH("ninguno",M24),0)>0, 0, P24 )))))))))) | Y24: =IF(T24="","",$W24-SUMIFS($X:$X,$A:$A,$A24)) | Z24: =IF(T24="","", IF(OR($T24=Referencias!$Y$20,$T24=Referencias!$Y$21),1, IF(OR($T24=Referencias!$Y$18,$T24=Referencias!$Y$19),( PI()*((V24*P24)+(2*0.48*( V24*((0+(V24-1))/2) ))) )/100, V24*Y24 ))) | AB24: =IF(T24="","",Z24*U24*(1+AA24))
A25: 4B | W25: =IF($A25="", "", IF(T25="","", IF(I25="Circular",PI()*(J25^2)/4, IF(I25="Rectangular", J25*K25, IF(I25="Irregular", J25*K25, IF(I25="Junta delgada", J25*K25, IF(I25="Junta steeldeck",(K25+(IF(L25=0,1,IF(L25=1,2.5,IF(L25=2,Referencias!$BA$19,IF(L25=3,Referencias!$BA$34,IF(L25=4,4.5,L25)))))/100 ))*J25, IF(I25="Junta irregular", L25, IF(I25="Junta perimetral", J25*(K25), 0 ))))))))) | X25: =IF($A25="", "", IF(M25="","", IF(IFERROR(SEARCH("bandeja",M25),0)>0, N25*P25*Q25*R25, IF(IFERROR(SEARCH("tubería",M25),0)>0, N25*PI()*(P25^2)/4, IF(IFERROR(SEARCH("circular",M25),0)>0, N25*PI()*(P25^2)/4, IF(IFERROR(SEARCH("rectangular",M25),0)>0, N25*P25*Q25, IF(IFERROR(SEARCH("cable",M25),0)>0, N25*PI()*(P25^2)/4, IF(IFERROR(SEARCH("caja",M25),0)>0, N25*P25*Q25, IF( IFERROR(SEARCH("blindobarra",M25),0)>0, N25*P25*Q25, IF( IFERROR(SEARCH("ninguno",M25),0)>0, 0, P25 )))))))))) | Y25: =IF(T25="","",$W25-SUMIFS($X:$X,$A:$A,$A25)) | Z25: =IF(T25="","", IF(OR($T25=Referencias!$Y$20,$T25=Referencias!$Y$21),1, IF(OR($T25=Referencias!$Y$18,$T25=Referencias!$Y$19),( PI()*((V25*P25)+(2*0.48*( V25*((0+(V25-1))/2) ))) )/100, V25*Y25 ))) | AB25: =IF(T25="","",Z25*U25*(1+AA25))
A26: 5A | W26: =IF($A26="", "", IF(T26="","", IF(I26="Circular",PI()*(J26^2)/4, IF(I26="Rectangular", J26*K26, IF(I26="Irregular", J26*K26, IF(I26="Junta delgada", J26*K26, IF(I26="Junta steeldeck",(K26+(IF(L26=0,1,IF(L26=1,2.5,IF(L26=2,Referencias!$BA$19,IF(L26=3,Referencias!$BA$34,IF(L26=4,4.5,L26)))))/100 ))*J26, IF(I26="Junta irregular", L26, IF(I26="Junta perimetral", J26*(K26), 0 ))))))))) | X26: =IF($A26="", "", IF(M26="","", IF(IFERROR(SEARCH("bandeja",M26),0)>0, N26*P26*Q26*R26, IF(IFERROR(SEARCH("tubería",M26),0)>0, N26*PI()*(P26^2)/4, IF(IFERROR(SEARCH("circular",M26),0)>0, N26*PI()*(P26^2)/4, IF(IFERROR(SEARCH("rectangular",M26),0)>0, N26*P26*Q26, IF(IFERROR(SEARCH("cable",M26),0)>0, N26*PI()*(P26^2)/4, IF(IFERROR(SEARCH("caja",M26),0)>0, N26*P26*Q26, IF( IFERROR(SEARCH("blindobarra",M26),0)>0, N26*P26*Q26, IF( IFERROR(SEARCH("ninguno",M26),0)>0, 0, P26 )))))))))) | Y26: =IF(T26="","",$W26-SUMIFS($X:$X,$A:$A,$A26)) | Z26: =IF(T26="","", IF(OR($T26=Referencias!$Y$20,$T26=Referencias!$Y$21),1, IF(OR($T26=Referencias!$Y$18,$T26=Referencias!$Y$19),( PI()*((V26*P26)+(2*0.48*( V26*((0+(V26-1))/2) ))) )/100, V26*Y26 ))) | AB26: =IF(T26="","",Z26*U26*(1+AA26))
A27: 5A | W27: =IF($A27="", "", IF(T27="","", IF(I27="Circular",PI()*(J27^2)/4, IF(I27="Rectangular", J27*K27, IF(I27="Irregular", J27*K27, IF(I27="Junta delgada", J27*K27, IF(I27="Junta steeldeck",(K27+(IF(L27=0,1,IF(L27=1,2.5,IF(L27=2,Referencias!$BA$19,IF(L27=3,Referencias!$BA$34,IF(L27=4,4.5,L27)))))/100 ))*J27, IF(I27="Junta irregular", L27, IF(I27="Junta perimetral", J27*(K27), 0 ))))))))) | X27: =IF($A27="", "", IF(M27="","", IF(IFERROR(SEARCH("bandeja",M27),0)>0, N27*P27*Q27*R27, IF(IFERROR(SEARCH("tubería",M27),0)>0, N27*PI()*(P27^2)/4, IF(IFERROR(SEARCH("circular",M27),0)>0, N27*PI()*(P27^2)/4, IF(IFERROR(SEARCH("rectangular",M27),0)>0, N27*P27*Q27, IF(IFERROR(SEARCH("cable",M27),0)>0, N27*PI()*(P27^2)/4, IF(IFERROR(SEARCH("caja",M27),0)>0, N27*P27*Q27, IF( IFERROR(SEARCH("blindobarra",M27),0)>0, N27*P27*Q27, IF( IFERROR(SEARCH("ninguno",M27),0)>0, 0, P27 )))))))))) | Y27: =IF(T27="","",$W27-SUMIFS($X:$X,$A:$A,$A27)) | Z27: =IF(T27="","", IF(OR($T27=Referencias!$Y$20,$T27=Referencias!$Y$21),1, IF(OR($T27=Referencias!$Y$18,$T27=Referencias!$Y$19),( PI()*((V27*P27)+(2*0.48*( V27*((0+(V27-1))/2) ))) )/100, V27*Y27 ))) | AB27: =IF(T27="","",Z27*U27*(1+AA27))
A28: 5B | W28: =IF($A28="", "", IF(T28="","", IF(I28="Circular",PI()*(J28^2)/4, IF(I28="Rectangular", J28*K28, IF(I28="Irregular", J28*K28, IF(I28="Junta delgada", J28*K28, IF(I28="Junta steeldeck",(K28+(IF(L28=0,1,IF(L28=1,2.5,IF(L28=2,Referencias!$BA$19,IF(L28=3,Referencias!$BA$34,IF(L28=4,4.5,L28)))))/100 ))*J28, IF(I28="Junta irregular", L28, IF(I28="Junta perimetral", J28*(K28), 0 ))))))))) | X28: =IF($A28="", "", IF(M28="","", IF(IFERROR(SEARCH("bandeja",M28),0)>0, N28*P28*Q28*R28, IF(IFERROR(SEARCH("tubería",M28),0)>0, N28*PI()*(P28^2)/4, IF(IFERROR(SEARCH("circular",M28),0)>0, N28*PI()*(P28^2)/4, IF(IFERROR(SEARCH("rectangular",M28),0)>0, N28*P28*Q28, IF(IFERROR(SEARCH("cable",M28),0)>0, N28*PI()*(P28^2)/4, IF(IFERROR(SEARCH("caja",M28),0)>0, N28*P28*Q28, IF( IFERROR(SEARCH("blindobarra",M28),0)>0, N28*P28*Q28, IF( IFERROR(SEARCH("ninguno",M28),0)>0, 0, P28 )))))))))) | Y28: =IF(T28="","",$W28-SUMIFS($X:$X,$A:$A,$A28)) | Z28: =IF(T28="","", IF(OR($T28=Referencias!$Y$20,$T28=Referencias!$Y$21),1, IF(OR($T28=Referencias!$Y$18,$T28=Referencias!$Y$19),( PI()*((V28*P28)+(2*0.48*( V28*((0+(V28-1))/2) ))) )/100, V28*Y28 ))) | AB28: =IF(T28="","",Z28*U28*(1+AA28))
A29: 5B | W29: =IF($A29="", "", IF(T29="","", IF(I29="Circular",PI()*(J29^2)/4, IF(I29="Rectangular", J29*K29, IF(I29="Irregular", J29*K29, IF(I29="Junta delgada", J29*K29, IF(I29="Junta steeldeck",(K29+(IF(L29=0,1,IF(L29=1,2.5,IF(L29=2,Referencias!$BA$19,IF(L29=3,Referencias!$BA$34,IF(L29=4,4.5,L29)))))/100 ))*J29, IF(I29="Junta irregular", L29, IF(I29="Junta perimetral", J29*(K29), 0 ))))))))) | X29: =IF($A29="", "", IF(M29="","", IF(IFERROR(SEARCH("bandeja",M29),0)>0, N29*P29*Q29*R29, IF(IFERROR(SEARCH("tubería",M29),0)>0, N29*PI()*(P29^2)/4, IF(IFERROR(SEARCH("circular",M29),0)>0, N29*PI()*(P29^2)/4, IF(IFERROR(SEARCH("rectangular",M29),0)>0, N29*P29*Q29, IF(IFERROR(SEARCH("cable",M29),0)>0, N29*PI()*(P29^2)/4, IF(IFERROR(SEARCH("caja",M29),0)>0, N29*P29*Q29, IF( IFERROR(SEARCH("blindobarra",M29),0)>0, N29*P29*Q29, IF( IFERROR(SEARCH("ninguno",M29),0)>0, 0, P29 )))))))))) | Y29: =IF(T29="","",$W29-SUMIFS($X:$X,$A:$A,$A29)) | Z29: =IF(T29="","", IF(OR($T29=Referencias!$Y$20,$T29=Referencias!$Y$21),1, IF(OR($T29=Referencias!$Y$18,$T29=Referencias!$Y$19),( PI()*((V29*P29)+(2*0.48*( V29*((0+(V29-1))/2) ))) )/100, V29*Y29 ))) | AB29: =IF(T29="","",Z29*U29*(1+AA29))
... A46: 9B | W46: =IF($A46="", "", IF(T46="","", IF(I46="Circular",PI()*(J46^2)/4, IF(I46="Rectangular", J46*K46, IF(I46="Irregular", J46*K46, IF(I46="Junta delgada", J46*K46, IF(I46="Junta steeldeck",(K46+(IF(L46=0,1,IF(L46=1,2.5,IF(L46=2,Referencias!$BA$19,IF(L46=3,Referencias!$BA$34,IF(L46=4,4.5,L46)))))/100 ))*J46, IF(I46="Junta irregular", L46, IF(I46="Junta perimetral", J46*(K46), 0 ))))))))) | X46: =IF($A46="", "", IF(M46="","", IF(IFERROR(SEARCH("bandeja",M46),0)>0, N46*P46*Q46*R46, IF(IFERROR(SEARCH("tubería",M46),0)>0, N46*PI()*(P46^2)/4, IF(IFERROR(SEARCH("circular",M46),0)>0, N46*PI()*(P46^2)/4, IF(IFERROR(SEARCH("rectangular",M46),0)>0, N46*P46*Q46, IF(IFERROR(SEARCH("cable",M46),0)>0, N46*PI()*(P46^2)/4, IF(IFERROR(SEARCH("caja",M46),0)>0, N46*P46*Q46, IF( IFERROR(SEARCH("blindobarra",M46),0)>0, N46*P46*Q46, IF( IFERROR(SEARCH("ninguno",M46),0)>0, 0, P46 )))))))))) | Y46: =IF(T46="","",$W46-SUMIFS($X:$X,$A:$A,$A46)) | Z46: =IF(T46="","", IF(OR($T46=Referencias!$Y$20,$T46=Referencias!$Y$21),1, IF(OR($T46=Referencias!$Y$18,$T46=Referencias!$Y$19),( PI()*((V46*P46)+(2*0.48*( V46*((0+(V46-1))/2) ))) )/100, V46*Y46 ))) | AB46: =IF(T46="","",Z46*U46*(1+AA46))
A47: 10 | W47: =IF($A47="", "", IF(T47="","", IF(I47="Circular",PI()*(J47^2)/4, IF(I47="Rectangular", J47*K47, IF(I47="Irregular", J47*K47, IF(I47="Junta delgada", J47*K47, IF(I47="Junta steeldeck",(K47+(IF(L47=0,1,IF(L47=1,2.5,IF(L47=2,Referencias!$BA$19,IF(L47=3,Referencias!$BA$34,IF(L47=4,4.5,L47)))))/100 ))*J47, IF(I47="Junta irregular", L47, IF(I47="Junta perimetral", J47*(K47), 0 ))))))))) | X47: =IF($A47="", "", IF(M47="","", IF(IFERROR(SEARCH("bandeja",M47),0)>0, N47*P47*Q47*R47, IF(IFERROR(SEARCH("tubería",M47),0)>0, N47*PI()*(P47^2)/4, IF(IFERROR(SEARCH("circular",M47),0)>0, N47*PI()*(P47^2)/4, IF(IFERROR(SEARCH("rectangular",M47),0)>0, N47*P47*Q47, IF(IFERROR(SEARCH("cable",M47),0)>0, N47*PI()*(P47^2)/4, IF(IFERROR(SEARCH("caja",M47),0)>0, N47*P47*Q47, IF( IFERROR(SEARCH("blindobarra",M47),0)>0, N47*P47*Q47, IF( IFERROR(SEARCH("ninguno",M47),0)>0, 0, P47 )))))))))) | Y47: =IF(T47="","",$W47-SUMIFS($X:$X,$A:$A,$A47)) | Z47: =IF(T47="","", IF(OR($T47=Referencias!$Y$20,$T47=Referencias!$Y$21),1, IF(OR($T47=Referencias!$Y$18,$T47=Referencias!$Y$19),( PI()*((V47*P47)+(2*0.48*( V47*((0+(V47-1))/2) ))) )/100, V47*Y47 ))) | AB47: =IF(T47="","",Z47*U47*(1+AA47))
A48: 10 | W48: =IF($A48="", "", IF(T48="","", IF(I48="Circular",PI()*(J48^2)/4, IF(I48="Rectangular", J48*K48, IF(I48="Irregular", J48*K48, IF(I48="Junta delgada", J48*K48, IF(I48="Junta steeldeck",(K48+(IF(L48=0,1,IF(L48=1,2.5,IF(L48=2,Referencias!$BA$19,IF(L48=3,Referencias!$BA$34,IF(L48=4,4.5,L48)))))/100 ))*J48, IF(I48="Junta irregular", L48, IF(I48="Junta perimetral", J48*(K48), 0 ))))))))) | X48: =IF($A48="", "", IF(M48="","", IF(IFERROR(SEARCH("bandeja",M48),0)>0, N48*P48*Q48*R48, IF(IFERROR(SEARCH("tubería",M48),0)>0, N48*PI()*(P48^2)/4, IF(IFERROR(SEARCH("circular",M48),0)>0, N48*PI()*(P48^2)/4, IF(IFERROR(SEARCH("rectangular",M48),0)>0, N48*P48*Q48, IF(IFERROR(SEARCH("cable",M48),0)>0, N48*PI()*(P48^2)/4, IF(IFERROR(SEARCH("caja",M48),0)>0, N48*P48*Q48, IF( IFERROR(SEARCH("blindobarra",M48),0)>0, N48*P48*Q48, IF( IFERROR(SEARCH("ninguno",M48),0)>0, 0, P48 )))))))))) | Y48: =IF(T48="","",$W48-SUMIFS($X:$X,$A:$A,$A48)) | Z48: =IF(T48="","", IF(OR($T48=Referencias!$Y$20,$T48=Referencias!$Y$21),1, IF(OR($T48=Referencias!$Y$18,$T48=Referencias!$Y$19),( PI()*((V48*P48)+(2*0.48*( V48*((0+(V48-1))/2) ))) )/100, V48*Y48 ))) | AB48: =IF(T48="","",Z48*U48*(1+AA48))

Sheet Informe preliminar
A2: Para / To: | D2: De / From: | F2: Fecha /Date:
A3: ='Informe - Planilla'!A3 -> CLIENTE | D3: ='Informe - Planilla'!C3 -> DEPARTAMENTO | F3: =TODAY() -> 42432
A4: ='Informe - Planilla'!A4 -> Nombre de destinatario | D4: ='Informe - Planilla'!C4 -> Nombre de remitente
A5: Asunto / Subject: | F5: Memo:
A6: ='Informe - Planilla'!A6 -> Descripción del proyecto; incluir nombre de la obra/proyecto. | D6: ='Informe - Planilla'!C6:D6 -> 0 | F6: ='Informe - Planilla'!E6 -> HES-FS-…
A9: R E S U M E N E J E C U T I V O
A11: Observaciones Generales
A13: Los sellos cortafuegos requieren de una revisión y un juicio de ingeniería (EJ) específico para el caso.
A15: Las cantidades estimadas se calculan con base en la certificación UL más apróximada.
A17: La información presentada en este documento debe ser validada por el responsable del proyecto. Hilti no se responsabiliza
A18: por cambios en las cantidades debidos a cambios en diseño/obra, por mal manejo y/o manipulación de los mismos.
A20: Resumen de sellos cortafuego por instalar y elementos a proteger
A22: Las siguientes cantidades resumen cuantitativamente la cantidad de protección que se requiere para el proyecto en términos de cuantos sellos cortafuego se han especificado para proteger cuantos elementos pasantes, en juntas y en sellos de fachadas y perimetrales.
C24: Detalles de sellos CF
D26: =IF(SUMIF('Informe - Planilla'!$O:$O,C26,'Informe - Planilla'!$P:$P)<=0,"",SUMIF('Informe - Planilla'!$O:$O,C26,'Informe - Planilla'!$P:$P))
B27: =IF((COUNTIFS('Informe - Planilla'!$I:$I,"Rectangular",'Informe - Planilla'!$G:$G,"<>"&"")+COUNTIFS('Informe - Planilla'!$I:$I,"Circular",'Informe - Planilla'!$G:$G,"<>"&"")+COUNTIFS('Informe - Planilla'!$I:$I,"Irregular",'Informe - Planilla'!$G:$G,"<>"&""))<=0,"",COUNTIFS('Informe - Planilla'!$I:$I,"Rectangular",'Informe - Planilla'!$G:$G,"<>"&"")+COUNTIFS('Informe - Planilla'!$I:$I,"Circular",'Informe - Planilla'!$G:$G,"<>"&"")+COUNTIFS('Informe - Planilla'!$I:$I,"Irregular",'Informe - Planilla'!$G:$G,"<>"&"")) | C27: Sellos de pases en muros/pisos/techos
B28: =IF(COUNTIFS('Informe - Planilla'!$I:$I,"Junta delgada",'Informe - Planilla'!$G:$G,"<>"&"")+COUNTIFS('Informe - Planilla'!$I:$I,"Junta steeldeck",'Informe - Planilla'!$G:$G,"<>"&"")+COUNTIFS('Informe - Planilla'!$I:$I,"Junta irregular",'Informe - Planilla'!$G:$G,"<>"&"")<=0,"",COUNTIFS('Informe - Planilla'!$I:$I,"Junta delgada",'Informe - Planilla'!$G:$G,"<>"&"")+COUNTIFS('Informe - Planilla'!$I:$I,"Junta steeldeck",'Informe - Planilla'!$G:$G,"<>"&"")+COUNTIFS('Informe - Planilla'!$I:$I,"Junta irregular",'Informe - Planilla'!$G:$G,"<>"&"")) | C28: Sellos de juntas
B29: =IF(COUNTIFS('Informe - Planilla'!$I:$I,"Junta perimetral",'Informe - Planilla'!$G:$G,"<>"&"")<=0,"",COUNTIFS('Informe - Planilla'!$I:$I,"Junta perimetral",'Informe - Planilla'!$G:$G,"<>"&"")) | C29: Sellos perimetrales o de fachada
D30: =IF(SUMIF('Informe - Planilla'!$O:$O,C30,'Informe - Planilla'!$P:$P)<=0,"",SUMIF('Informe - Planilla'!$O:$O,C30,'Informe - Planilla'!$P:$P))
B31: =IF(SUMIF('Informe - Planilla'!$M:$M,C31,'Informe - Planilla'!$N:$N)<=0,"",SUMIF('Informe - Planilla'!$M:$M,C31,'Informe - Planilla'!$N:$N)) | C31: =Referencias!$U6 -> Ninguno (Blank)
B32: =IF(SUMIF('Informe - Planilla'!$M:$M,C32,'Informe - Planilla'!$N:$N)<=0,"",SUMIF('Informe - Planilla'!$M:$M,C32,'Informe - Planilla'!$N:$N)) -> 1 | C32: =Referencias!$U7 -> Bandeja PC
B33: =IF(SUMIF('Informe - Planilla'!$M:$M,C33,'Informe - Planilla'!$N:$N)<=0,"",SUMIF('Informe - Planilla'!$M:$M,C33,'Informe - Planilla'!$N:$N)) | C33: =Referencias!$U8 -> Blindobarra
B34: =IF(SUMIF('Informe - Planilla'!$M:$M,C34,'Informe - Planilla'!$N:$N)<=0,"",SUMIF('Informe - Planilla'!$M:$M,C34,'Informe - Planilla'!$N:$N)) | C34: =Referencias!$U9 -> Cable/Grupo de cables
B35: =IF(SUMIF('Informe - Planilla'!$M:$M,C35,'Informe - Planilla'!$N:$N)<=0,"",SUMIF('Informe - Planilla'!$M:$M,C35,'Informe - Planilla'!$N:$N)) | C35: =Referencias!$U10 -> Ducto circular
B36: =IF(SUMIF('Informe - Planilla'!$M:$M,C36,'Informe - Planilla'!$N:$N)<=0,"",SUMIF('Informe - Planilla'!$M:$M,C36,'Informe - Planilla'!$N:$N)) | C36: =Referencias!$U11 -> Ducto rectangular
B37: =IF(SUMIF('Informe - Planilla'!$M:$M,C37,'Informe - Planilla'!$N:$N)<=0,"",SUMIF('Informe - Planilla'!$M:$M,C37,'Informe - Planilla'!$N:$N)) -> 1 | C37: =Referencias!$U12 -> Tubería metal
B38: =IF(SUMIF('Informe - Planilla'!$M:$M,C38,'Informe - Planilla'!$N:$N)<=0,"",SUMIF('Informe - Planilla'!$M:$M,C38,'Informe - Planilla'!$N:$N)) -> 1 | C38: =Referencias!$U13 -> Tubería no metal
B39: =IF(SUMIF('Informe - Planilla'!$M:$M,C39,'Informe - Planilla'!$N:$N)<=0,"",SUMIF('Informe - Planilla'!$M:$M,C39,'Informe - Planilla'!$N:$N)) | C39: =Referencias!$U14 -> Tubería metal aislada
B40: =IF(SUMIF('Informe - Planilla'!$M:$M,C40,'Informe - Planilla'!$N:$N)<=0,"",SUMIF('Informe - Planilla'!$M:$M,C40,'Informe - Planilla'!$N:$N)) | C40: =Referencias!$U15 -> Tubería no metal aislada
B41: =IF(SUMIF('Informe - Planilla'!$M:$M,C41,'Informe - Planilla'!$N:$N)<=0,"",SUMIF('Informe - Planilla'!$M:$M,C41,'Informe - Planilla'!$N:$N)) | C41: =Referencias!$U16 -> Tubería hidro-llena
B42: =IF(SUMIF('Informe - Planilla'!$M:$M,C42,'Informe - Planilla'!$N:$N)<=0,"",SUMIF('Informe - Planilla'!$M:$M,C42,'Informe - Planilla'!$N:$N)) | C42: =Referencias!$U17 -> Tubería hidro-parcial
... B45: =IF(SUMIF('Informe - Planilla'!$M:$M,C45,'Informe - Planilla'!$N:$N)<=0,"",SUMIF('Informe - Planilla'!$M:$M,C45,'Informe - Planilla'!$N:$N)) | C45: =Referencias!$U20 -> Otro
A48: Resumen de productos especificados
B51: PRODUCTO HILTI | D51: REQUERIMIENTO TOTAL | E51: UNIDADES ESPECIFICADAS | I51: PRECIO DE VENTA | J51: SUBTOTAL ESPECIFICACION
B52: Descripción | C52: Código | H52: Rendimiento Unitario
B53: =Referencias!$Y6 -> CFS-WB | C53: =VLOOKUP(B53,Referencias!Y6:AC21,3,FALSE) -> 236993 | D53: =IF(SUMIF('Informe - Planilla'!$T:$T,$B53,'Informe - Planilla'!$AB:$AB)<=0,"",SUMIF('Informe - Planilla'!$T:$T,$B53,'Informe - Planilla'!$AB:$AB)) -> 2579.85 | E53: =IFERROR(ROUNDUP(D53/H53,0),"") -> 1 | F53: Paca de lana | H53: =122*61*10 -> 74420 | I53: 40000 | J53: =IFERROR(E53*I53,"") -> 40000
B54: =Referencias!$Y7 -> CF-AS CJP | C54: =VLOOKUP(B54,Referencias!Y7:AC22,3,FALSE) -> 2005479 | D54: =IF(SUMIF('Informe - Planilla'!$T:$T,$B54,'Informe - Planilla'!$AB:$AB)<=0,"",SUMIF('Informe - Planilla'!$T:$T,$B54,'Informe - Planilla'!$AB:$AB)) | E54: =IFERROR(ROUNDUP(D54/H54,0),"") | F54: Foil/Cartucho | H54: 45307 | I54: 41625 | J54: =IFERROR(E54*I54,"")
B55: =Referencias!$Y8 -> FS-ONE Max | C55: =VLOOKUP(B55,Referencias!Y8:AC23,IF(F55="Foil/Cartucho",3,IF(F55="Caneca",4,"-")),FALSE) -> 311387 | D55: =IF(SUMIF('Informe - Planilla'!$T:$T,$B55,'Informe - Planilla'!$AB:$AB)<=0,"",SUMIF('Informe - Planilla'!$T:$T,$B55,'Informe - Planilla'!$AB:$AB)) -> 598.97854 | E55: =IFERROR(ROUNDUP(D55/H55,0),"") -> 1 | F55: Foil/Cartucho | H55: =IF(F55="Foil/Cartucho",600,18927) -> 600 | I55: =IF(F55="Foil/Cartucho",126000,2062500) -> 126000 | J55: =IFERROR(E55*I55,"") -> 126000
B56: =Referencias!$Y9 -> CP 620 | C56: =VLOOKUP(B56,Referencias!Y9:AC24,3,FALSE) -> 338725 | D56: =IF(SUMIF('Informe - Planilla'!$T:$T,$B56,'Informe - Planilla'!$AB:$AB)<=0,"",SUMIF('Informe - Planilla'!$T:$T,$B56,'Informe - Planilla'!$AB:$AB)) | E56: =IFERROR(ROUNDUP(D56/H56,0),"") | F56: Foil/Cartucho | H56: 1803 | I56: 213750 | J56: =IFERROR(E56*I56,"")
B57: =Referencias!$Y10 -> CP 618 | C57: =VLOOKUP(B57,Referencias!Y10:AC25,3,FALSE) -> 314721 | D57: =IF(SUMIF('Informe - Planilla'!$T:$T,$B57,'Informe - Planilla'!$AB:$AB)<=0,"",SUMIF('Informe - Planilla'!$T:$T,$B57,'Informe - Planilla'!$AB:$AB)) | E57: =IFERROR(ROUNDUP(D57/H57,0),"") | F57: Barra moldeable | H57: 295 | I57: 78375 | J57: =IFERROR(E57*I57,"")
...

Sheet observaciones
B2: INSERTAR LAS IMÁGENES DEL REGISTRO FOTOGRÁFICO VINCULADAS A LA PLANILLA.
B4: Indicar el código de la especificación + la imagen en cada caso.

Sheet Referencias
B4: TIPO DE BASE | G4: MAETRIAL BASE | K4: FORMAS DE PERFORACIÓN | O4: ACTIVIDAD DE PASANTES | T4: PASANTES COMUNES | X4: PRODUCTOS Hilti | AF4: RENDIMIENTOS DE CINTA FS | AN4: RENDIMIENTOS DE MORTERO FS | AV4: ESTIMACIÓN DE AREA DE SELLO | JUNTAS STEELDECK
AG5: El rendimiento de las cintas están caculadas con base en las siguientes expresiones: | AO5: El rendimiento del mortero está caculado con base en las siguientes expresiones: | AW5: El volumen de llenado de la junta depende del tipo de perfil y de la separación con el murode apoyo.
C6: Muro | D6: W | H6: Mamposteria (arcilla, concreto, etc) | L6: Circular | P6: Altamente Activo | Q6: AA | U6: Ninguno (Blank) | Y6: CFS-WB | Z6: Lana mineral 122x61x10cm | AA6: 236993 | AB6: - | AC6: -
C7: Muro-Muro | D7: WW | H7: Concreto (normal, ligero, etc) | L7: Rectangular | P7: Moderadamente activo | Q7: MA | U7: Bandeja PC | Y7: CF-AS CJP | Z7: Espuma poliuretano | AA7: 2005479 | AB7: - | AC7: -
C8: Piso | D8: F | H8: Drywall/Yeso | L8: Irregular | P8: Inactivo | Q8: IA | U8: Blindobarra | Y8: FS-ONE Max | Z8: Sellador intumescente | AA8: 311387 | AB8: 259578 | AC8: -
C9: Piso-Muro | D9: FW | H9: Madera/Vidrio/Otros | L9: Junta delgada | U9: Cable/Grupo de cables | Y9: CP 620 | Z9: Espuma intumescente | AA9: 338725 | AB9: - | AC9: - | AO9: Relación: | AP9: 3 | AQ9: 1 | AW9: Lámina colaborante de 2" | AZ9: 0
C10: Piso-Piso | D10: FF | L10: Junta steeldeck | U10: Ducto circular | Y10: CP 618 | Z10: Sellante intumescente | AA10: 314721 | AB10: - | AC10: - | AW10: espesor de losa | AX10: concreto | AY10: seccion concreto | AZ10: espesor junta | BA10: area de junta
C11: Techo | D11: C | L11: Junta irregular | U11: Ducto rectangular | Y11: CFS BL | Z11: Ladrillo intumescente | AA11: 2030020 | AB11: - | AC11: - | AP11: 13.6 | AQ11: Peso mortero | AW11: mm | AX11: m3/m2 | AY11: m2/m | AZ11: mm | BA11: cm2/m
C12: Techo-Muro | D12: HW | L12: Junta perimetral | U12: Tubería metal | Y12: CP 637 | Z12: Mortero cortafuego | AA12: 340645 | AB12: - | AC12: - | AP12: =AP11/AP9 -> 4.5333333 | AQ12: Peso agua | AW12: 100 | AX12: =AVERAGE(AX43,AY43) -> 0.0715 | AY12: =+AX12/1 -> 0.0715 | AZ12: =$AZ$9 -> 0 | BA12: =((((AW12+AZ12)/1000)*1)-AY12)*10000 -> 285
C13: Muro Cortina / fachada | D13: CW | U13: Tubería no metal | Y13: CFS-S SIL GG | Z13: Sellador elastomérico | AA13: 2076883 | AB13: 314270 | AC13: - | AP13: =SUM(AP11:AP12) -> 18.133333 | AQ13: Peso total mezcla | AW13: 110 | AX13: =AVERAGE(AX44,AY44) -> 0.0815 | AY13: =+AX13/1 -> 0.0815 | AZ13: =$AZ$9 -> 0 | BA13: =((((AW13+AZ13)/1000)*1)-AY13)*10000 -> 285
U14: Tubería metal aislada | Y14: CFS-SP WB | Z14: Spray para juntas (rojo) | AA14: 430792 | AB14: - | AC14: - | AW14: 120 | AX14: =AVERAGE(AX45,AY45) -> 0.0915 | AY14: =+AX14/1 -> 0.0915 | AZ14: =$AZ$9 -> 0 | BA14: =((((AW14+AZ14)/1000)*1)-AY14)*10000 -> 285
U15: Tubería no metal aislada | Y15: CP 606 | Z15: Sellante acrilico flexible | AA15: 209637 | AB15: - | AC15: - | AO15: Determinación de densidad de mezcla | AW15: 130 | AX15: =AVERAGE(AX46,AY46) -> 0.1015 | AY15: =+AX15/1 -> 0.1015 | AZ15: =$AZ$9 -> 0 | BA15: =((((AW15+AZ15)/1000)*1)-AY15)*10000 -> 285
U16: Tubería hidro-llena | Y16: CP 678 | Z16: Pintura intumescente | AA16: 334892 | AB16: - | AC16: - | AW16: 140 | AX16: =AVERAGE(AX47,AY47) -> 0.1115 | AY16: =+AX16/1 -> 0.1115 | AZ16: =$AZ$9 -> 0 | BA16: =((((AW16+AZ16)/1000)*1)-AY16)*10000 -> 285
U17: Tubería hidro-parcial | Y17: CP 679 A | Z17: Pintura intumescente | AA17: 372097 | AB17: - | AC17: - | AO17: 900 | AQ17: Densidad mortero | AW17: 150 | AX17: =AVERAGE(AX48,AY48) -> 0.1215 | AY17: =+AX17/1 -> 0.1215 | AZ17: =$AZ$9 -> 0 | BA17: =((((AW17+AZ17)/1000)*1)-AY17)*10000 -> 285
U18: Caja (interruptor u otros) | Y18: CP 648E 1" | Z18: Cinta intumescente | AA18: 304308 | AB18: - | AC18: - | AO18: 1000 | AP18: 1000 | AQ18: Densidad agua | AW18: 160 | AZ18: =$AZ$9 -> 0
U19: Componente mecanico | Y19: CP 648E 1-¾" | Z19: Cinta intumescente | AA19: 304309 | AB19: - | AC19: - | AO19: =((AP11*AO17)+(AP12*AO18))/(AP13) -> 925 | AQ19: Densidad promedio | BA19: =AVERAGE(BA12:BA18) -> 285
U20: Otro | Y20: CP 643-110/4" | Z20: Collarín cortafuego | AA20: 304329 | AB20: - | AC20: - | AQ20: (promedio ponderado en peso)
Y21: CP 643-160/6" | Z21: Collarín cortafuego | AA21: 304331 | AB21: - | AC21: - | AW21: Lámina colaborante de 3" | AZ21: 0
AO22: Determinación del volumen colocado | AW22: espesor de losa | AX22: concreto | AY22: seccion concreto | AZ22: espesor junta | BA22: area de junta
Y23: Foil/Cartucho | AW23: mm | AX23: m3/m2 | AY23: m2/m | AZ23: mm | BA23: cm2/m
Y24: Caneca | AO24: =AP13 -> 18.133333 | AQ24: Peso de mezcla | AW24: 120 | AZ24: =$AZ$9 -> 0
AO25: =AO19 -> 925 | AP25: 1000 | AQ25: Densidad de mezcla | AW25: 130 | AX25: =AVERAGE(AZ46,BA46) -> 0.091 | AY25: =+AX25/1 -> 0.091 | AZ25: =$AZ$9 -> 0 | BA25: =((((AW25+AZ25)/1000)*1)-AY25)*10000 -> 390
AG26: A1 = | AH26: 0 | AO26: =AO24/AO25 -> 0.019603604 | AQ26: Volumen de mezcla | AW26: 140 | AX26: =AVERAGE(AZ47,BA47) -> 0.1005 | AY26: =+AX26/1 -> 0.1005 | AZ26: =$AZ$9 -> 0 | BA26: =((((AW26+AZ26)/1000)*1)-AY26)*10000 -> 395
AG27: An = | AH27: n – 1 | AW27: 150 | AX27: =AVERAGE(AZ48,BA48) -> 0.1105 | AY27: =+AX27/1 -> 0.1105 | AZ27: =$AZ$9 -> 0 | BA27: =((((AW27+AZ27)/1000)*1)-AY27)*10000 -> 395
AO28: Según este resultado, 1 bulto de mortero, mezclado con agua en la relación indicada, tiene un volumen de: | AW28: 160 | AX28: =AVERAGE(AZ49,BA49) -> 0.12 | AY28: =+AX28/1 -> 0.12 | AZ28: =$AZ$9 -> 0 | BA28: =((((AW28+AZ28)/1000)*1)-AY28)*10000 -> 400
AG29: Ejemplo de cálculo | AW29: 165 | AX29: =AVERAGE(AZ50,BA50) -> 0.13 | AY29: =+AX29/1 -> 0.13 | AZ29: =$AZ$9 -> 0 | BA29: =((((AW29+AZ29)/1000)*1)-AY29)*10000 -> 350
AW30: 180 | AX30: =AVERAGE(AZ51,BA51) -> 0.14 | AY30: =+AX30/1 -> 0.14 | AZ30: =$AZ$9 -> 0 | BA30: =((((AW30+AZ30)/1000)*1)-AY30)*10000 -> 400
AG31: capas | AH31: D0 | AI31: Sopt | AJ31: Sapx | AK31: error | AW31: 185 | AX31: =AVERAGE(AZ52,BA52) -> 0.15 | AY31: =+AX31/1 -> 0.15 | AZ31: =$AZ$9 -> 0 | BA31: =((((AW31+AZ31)/1000)*1)-AY31)*10000 -> 350
AG32: # | AH32: cm | AI32: cm | AJ32: cm | AK32: % | AO32: Volumen Colocado | AP32: =AO26*1000000 -> 19603.604 | AW32: 190 | AX32: =AVERAGE(AZ53,BA53) -> 0.16 | AY32: =+AX32/1 -> 0.16 | AZ32: =$AZ$9 -> 0 | BA32: =((((AW32+AZ32)/1000)*1)-AY32)*10000 -> 300
AG33: 1 | AH33: =4*2.54 -> 10.16 | AI33: =(AH33+((AG33-1)*2*0.48))*PI() -> 31.918581 | AJ33: =PI()*AH33*AG33 -> 31.918581 | AK33: =1-(+AJ33/AI33) -> 0 | AW33: 205 | AX33: =AVERAGE(AZ54,BA54) -> 0.17 | AY33: =+AX33/1 -> 0.17 | AZ33: =$AZ$9 -> 0 | BA33: =((((AW33+AZ33)/1000)*1)-AY33)*10000 -> 350
AG34: 2 | AH34: =4*2.54 -> 10.16 | AI34: =((AH33+((AG33-1)*2*0.48))*PI())+( (AH34+((AG34-1)*2*0.48))*PI() ) -> 66.853092 | AJ34: =PI()*AH34*AG34 -> 63.837163 | AK34: =1-(+AJ34/AI34) -> 0.045112782 | BA34: =AVERAGE(BA24:BA33) -> 370
AG35: 3 | AH35: =4*2.54 -> 10.16 | AI35: =( ((AH33+((AG33-1)*2*0.48))*PI())+( (AH34+((AG34-1)*2*0.48))*PI() ) )+( (AH35+((AG35-1)*2*0.48))*PI() ) -> 104.80353 | AJ35: =PI()*AH35*AG35 -> 95.755744 | AK35: =1-(+AJ35/AI35) -> 0.086330935
AG36: 4 | AH36: =4*2.54 -> 10.16 | AI36: =+AI35+( (AH36+((AG36-1)*2*0.48))*PI() ) -> 145.7699 | AJ36: =PI()*AH36*AG36 -> 127.67433 | AK36: =1-(+AJ36/AI36) -> 0.12413793
AG37: 5 | AH37: =4*2.54 -> 10.16 | AI37: =+AI36+( (AH37+((AG37-1)*2*0.48))*PI() ) -> 189.7522 | AJ37: =PI()*AH37*AG37 -> 159.59291 | AK37: =1-(+AJ37/AI37) -> 0.1589404
AG38: 6 | AH38: =4*2.54 -> 10.16 | AI38: =+AI37+( (AH38+((AG38-1)*2*0.48))*PI() ) -> 236.75042 | AJ38: =PI()*AH38*AG38 -> 191.51149 | AK38: =1-(+AJ38/AI38) -> 0.1910828 | AW38: CONSUMO CONCRETO
AG39: 7 | AH39: =4*2.54 -> 10.16 | AI39: =+AI38+( (AH39+((AG39-1)*2*0.48))*PI() ) -> 286.76458 | AJ39: =PI()*AH39*AG39 -> 223.43007 | AK39: =1-(+AJ39/AI39) -> 0.2208589 | AX39: COLMENA | AY39: ACESCO | BA39: OSTRILLION
AG40: 8 | AH40: =4*2.54 -> 10.16 | AI40: =+AI39+( (AH40+((AG40-1)*2*0.48))*PI() ) -> 339.79466 | AJ40: =PI()*AH40*AG40 -> 255.34865 | AK40: =1-(+AJ40/AI40) -> 0.24852071 | AW40: m3/m2
AG41: 9 | AH41: =4*2.54 -> 10.16 | AI41: =+AI40+( (AH41+((AG41-1)*2*0.48))*PI() ) -> 395.84067 | AJ41: =PI()*AH41*AG41 -> 287.26723 | AK41: =1-(+AJ41/AI41) -> 0.27428571
AG42: 10 | AH42: =4*2.54 -> 10.16 | AI42: =+AI41+( (AH42+((AG42-1)*2*0.48))*PI() ) -> 454.90262 | AJ42: =PI()*AH42*AG42 -> 319.18581 | AK42: =1-(+AJ42/AI42) -> 0.29834254 | AX42: 2" | AY42: 2" | AZ42: 3" | BA42: 3"
AW43: 100 | AX43: 0.071 | AY43: 0.072
...
